Workbook
Name Slicer_Ld_Create_Dt: #N/A
Name Slicer_Week_Ending: #N/A

Sheet Total Cube Data
A1: Week Ending | B1: Ld Create Dt | C1: Load Information Lookup.Destinations | D1: Outbound Lineup.Column3 | E1: Total Loads | F1: Total Loaded Cube | G1: Total Equip Cap | H1: Total Mvmt $ | I1: Destination
A2: 45717 | B2: 45712 | C2: SDFAS D | D2: PD2 | E2: 1 | F2: 552 | G2: 1982 | H2: 601 | I2: 4009 D
A3: 45717 | B3: 45714 | C3: SDFAS D | D3: PD2 | E3: 1 | F3: 26 | G3: 1982 | H3: 600.54 | I3: 4009 D
A4: 45724 | B4: 45721 | C4: SDFAS D | D4: PD2 | E4: 1 | F4: 685 | G4: 1982 | H4: 600.54 | I4: 4009 D
A5: 45717 | B5: 45712 | C5: SYRNY N | D5: PD1 | E5: 3 | F5: 6125 | G5: 9642 | H5: 899.48 | I5: 1329 N
A6: 45717 | B6: 45712 | C6: SYRNY N | D6: PD1 | E6: 3 | F6: 6125 | G6: 9642 | H6: 899.48 | I6: 1329 N
A7: 45717 | B7: 45713 | C7: SYRNY N | D7: PD1 | E7: 2 | F7: 2550 | G7: 5812 | H7: 539.69 | I7: 1329 N
A8: 45717 | B8: 45713 | C8: SYRNY N | D8: PD1 | E8: 2 | F8: 2550 | G8: 5812 | H8: 539.69 | I8: 1329 N
A9: 45717 | B9: 45714 | C9: SYRNY N | D9: PD1 | E9: 1 | F9: 2221 | G9: 3818 | H9: 372.32 | I9: 1329 N
A10: 45717 | B10: 45714 | C10: SYRNY N | D10: PD1 | E10: 1 | F10: 2221 | G10: 3818 | H10: 372.32 | I10: 1329 N
A11: 45717 | B11: 45715 | C11: SYRNY N | D11: PD1 | E11: 2 | F11: 4174 | G11: 5800 | H11: 540 | I11: 1329 N
A12: 45717 | B12: 45715 | C12: SYRNY N | D12: PD1 | E12: 2 | F12: 4174 | G12: 5800 | H12: 540 | I12: 1329 N
A13: 45717 | B13: 45716 | C13: SYRNY N | D13: PD1 | E13: 2 | F13: 4069 | G13: 5800 | H13: 552 | I13: 1329 N
... A209: 45724 | B209: 45722 | C209: BURMD N | D209: PD3 | E209: 1 | F209: 2922 | G209: 3830 | H209: 332.94 | I209: 2079 N

Sheet Pivots
A3: Row Labels | H3: Row Labels
A4: 45717 | H4: 45715
A5: Grand Total | H5: Grand Total
A8: Row Labels | B8: Sum of Total Loaded Cube | C8: Sum of Total Equip Cap | D8: Sum of Total Utilization | E8: Sum of Total Mvmt $ | H8: Row Labels | I8: Sum of Total Loaded Cube | J8: Sum of Total Equip Cap | K8: Sum of Total Utilization | L8: Sum of Total Mvmt $
A9: ALLPA P | B9: 3288 | C9: 3830 | D9: 0.85848564 | E9: 26 | H9: NBACA D | I9: 3264 | J9: 3818 | K9: 0.85489785 | L9: 4645.13
A10: FLDIN T | B10: 3216 | C10: 3830 | D10: 0.83968668 | E10: 1172.45 | H10: SMAGA T | I10: 3228 | J10: 3830 | K10: 0.84281984 | L10: 1501.81
A11: NBACA D | B11: 16006 | C11: 19138 | D11: 0.83634654 | E11: 21120.73 | H11: BURMD N | I11: 3129 | J11: 3818 | K11: 0.81953903 | L11: 332.94
A12: SMAGA T | B12: 17330 | C12: 21132 | D12: 0.82008329 | E12: 8017.85 | H12: NASNY P | I12: 1506 | J12: 1982 | K12: 0.75983855 | L12: 109.19
A13: EMPCA T | B13: 11974 | C13: 15284 | D13: 0.78343366 | E13: 17249.89 | H13: EMPCA T | I13: 2893 | J13: 3818 | K13: 0.75772656 | L13: 4118.14
A14: Grand Total | B14: 51814 | C14: 63214 | D14: 0.8196602 | E14: 47586.92 | H14: Grand Total | I14: 14020 | J14: 17266 | K14: 0.81200046 | L14: 10707.21
A17: Row Labels | B17: Sum of Total Loaded Cube | C17: Sum of Total Equip Cap | D17: Sum of Total Utilization | E17: Sum of Total Mvmt $ | H17: Row Labels | I17: Sum of Total Loaded Cube | J17: Sum of Total Equip Cap | K17: Sum of Total Utilization | L17: Sum of Total Mvmt $
A18: CRBNJ N | B18: 112 | C18: 3230 | D18: 0.034674923 | E18: 221.85 | H18: SADNJ N | I18: 632 | J18: 3830 | K18: 0.16501305 | L18: 212
A19: SDFAS D | B19: 578 | C19: 3964 | D19: 0.14581231 | E19: 1201.54 | H19: EZRPA N | I19: 790 | J19: 3830 | K19: 0.20626632 | L19: 182.58
A20: SADNJ N | B20: 2514 | C20: 9630 | D20: 0.26105919 | E20: 529.47 | H20: MEANJ N | I20: 968 | J20: 3818 | K20: 0.25353588 | L20: 214.2
A21: CHEMA T | B21: 1021 | C21: 3230 | D21: 0.31609907 | E21: 560.27 | H21: M43NY N | I21: 2079 | J21: 3450 | K21: 0.6026087 | L21: 184.37
A22: PHLPA P | B22: 1246 | C22: 3830 | D22: 0.32532637 | E22: 216.75 | H22: BAYNJ N | I22: 5128 | J22: 7660 | K22: 0.6694517 | L22: 408
A23: Grand Total | B23: 5471 | C23: 23884 | D23: 0.22906548 | E23: 2729.88 | H23: Grand Total | I23: 9597 | J23: 22588 | K23: 0.42487161 | L23: 1201.15
A26: Row Labels | B26: Sum of Total Utilization | C26: Sum of Total Mvmt $ | D26: Sum of Total Loads | H26: Row Labels | I26: Sum of Total Utilization | J26: Sum of Total Mvmt $ | K26: Sum of Total Loads
A27: PD5 | B27: 0.71329116 | C27: 70490.02 | D27: 55 | H27: PD3 | I27: 0.7487262 | J27: 3745.93 | K27: 4
A28: PD3 | B28: 0.68727221 | C28: 32751.34 | D28: 34 | H28: PD5 | I28: 0.73769151 | J28: 10267.14 | K28: 8
A29: PD2 | B29: 0.6640998 | C29: 6544.9 | D29: 27 | H29: PD1 | I29: 0.64681377 | J29: 3525.02 | K29: 9
A30: PD1 | B30: 0.63246422 | C30: 20490.19 | D30: 42 | H30: PD2 | I30: 0.58862827 | J30: 687.19 | K30: 4
A31: PD4 | B31: 0.56458152 | C31: 26018.42 | D31: 20 | H31: PD4 | I31: 0.55421687 | J31: 4859.33 | K31: 2
A32: Grand Total | B32: 0.66270581 | C32: 156294.87 | D32: 178 | H32: Grand Total | I32: 0.67060432 | J32: 23084.61 | K32: 27
A35: Row Labels | B35: Sum of Total Loaded Cube | C35: Sum of Total Equip Cap | D35: Sum of Total Utilization | E35: Sum of Total Mvmt $ | H35: Row Labels | I35: Sum of Total Loaded Cube | J35: Sum of Total Equip Cap | K35: Sum of Total Utilization | L35: Sum of Total Mvmt $
A36: PD1 | B36: 26145 | C36: 34410 | D36: 0.7598082 | E36: 12159.47 | H36: PD1 | I36: 19084 | J36: 26896 | K36: 0.70954789 | L36: 3342.44
A37: FLDIN T | B37: 3216 | C37: 3830 | D37: 0.83968668 | E37: 1172.45 | H37: MEBNC T | I37: 5608 | J37: 7636 | K37: 0.73441592 | L37: 1854.44
A38: MEBNC T | B38: 17280 | C38: 22932 | D38: 0.75353218 | E38: 5563.32 | H38: SYRNY N | I38: 8348 | J38: 11600 | K38: 0.71965517 | L38: 1080
A39: HASTX D | B39: 5649 | C39: 7648 | D39: 0.73862448 | E39: 5423.7 | H39: BAYNJ N | I39: 5128 | J39: 7660 | K39: 0.6694517 | L39: 408
A40: PD2 | B40: 52608 | C40: 69808 | D40: 0.7536099 | E40: 3458.6 | H40: Grand Total | I40: 19084 | J40: 26896 | K40: 0.70954789 | L40: 3342.44
A41: EZRPA S | B41: 46036 | C41: 60032 | D41: 0.76685768 | E41: 2922.12
A42: OREPA P | B42: 2663 | C42: 3830 | D42: 0.69530026 | E42: 209.1
A43: NASNY P | B43: 3909 | C43: 5946 | D43: 0.65741675 | E43: 327.38 | H43: Row Labels | I43: Sum of Total Loaded Cube | J43: Sum of Total Equip Cap | K43: Sum of Total Utilization | L43: Sum of Total Mvmt $
A44: PD3 | B44: 41028 | C44: 51724 | D44: 0.79321012 | E44: 25068.07 | H44: PD2 | I44: 7930 | J44: 13472 | K44: 0.58862827 | L44: 687.19
A45: SMAGA T | B45: 17330 | C45: 21132 | D45: 0.82008329 | E45: 8017.85 | H45: NASNY P | I45: 1506 | J45: 1982 | K45: 0.75983855 | L45: 109.19
A46: EMPCA A | B46: 2969 | C46: 3830 | D46: 0.77519582 | E46: 4118.14 | H46: EZRPA S | I46: 5792 | J46: 7660 | K46: 0.75613577 | L46: 366
A47: JACFL D | B47: 20729 | C47: 26762 | D47: 0.77456842 | E47: 12932.08 | H47: SADNJ N | I47: 632 | J47: 3830 | K47: 0.16501305 | L47: 212
A48: PD4 | B48: 24558 | C48: 30604 | D48: 0.80244412 | E48: 22408.06 | H48: Grand Total | I48: 7930 | J48: 13472 | K48: 0.58862827 | L48: 687.19
A49: NBACA D | B49: 16006 | C49: 19138 | D49: 0.83634654 | E49: 21120.73
A50: COLOH T | B50: 2940 | C50: 3830 | D50: 0.76762402 | E50: 853.83
...

Sheet Load Information Lookup
A1: Destinations | B1: SLICS | C1: Cetner | D1: SLICS | E1: Destinations
A2: 0703 P | B2: 703 | C2: LYNDHURST VILLAGE | D2: 703 P | E2: 0703 P
A3: 1006 P | B3: 1006 | C3: 43RD ST-3RD FLR PRE | D3: 1006 P | E3: 1006 P
A4: 1015 P | B4: 1015 | C4: 43RD ST-4TH FLR PRE | D4: 1015 P | E4: 1015 P
A5: 1017 P | B5: 1017 | C5: 43RD ST-2ND FLR PRE | D5: 1017 P | E5: 1017 P
A6: 1075 M | B6: 1075 | C6: YONKERS | D6: 1075 M | E6: 1075 M
A7: 1075 P | B7: 1075 | C7: YONKERS | D7: 1075 P | E7: 1075 P
A8: 1110 P | B8: 1110 | C8: QUEENS NORTH | D8: 1110 P | E8: 1110 P
A9: 1123 P | B9: 1123 | C9: OCEAN HILL | D9: 1123 P | E9: 1123 P
A10: 1164 P | B10: 1164 | C10: SPRINGFIELD | D10: 1164 P | E10: 1164 P
A11: 1170 P | B11: 1170 | C11: SUFFOLK-PATCHOGUE | D11: 1170 P | E11: 1170 P
A12: ALLPA P | B12: 1819 | C12: ALLENTOWN SORT | D12: 1819 P | E12: ALLPA P
A13: ATLGA T | B13: 3039 | C13: ATLGA T | D13: 3039 T | E13: ATLGA T
... A159: WHITN N | B159: 3719 | C159: WHITES CREEK HUB | D159: 3719 N | E159: WHITN N

Sheet Outbound Lineup
A1: PD1
A2: 96 | B2: 0810 P | C2: PD1
A3: 97 | B3: SYRNY N | C3: PD1
A4: 98 | B4: NIACT P | C4: PD1
A5: 99 | B5: SYRNY N | C5: PD1
A6: 100 | B6: VIRPA P | C6: PD1
A7: 101 | C7: PD1
A8: 102 | B8: SCRPA P | C8: PD1
A9: 103 | B9: MEBNC T | C9: PD1
A10: 104 | B10: REAPA P | C10: PD1
A11: 105 | B11: MEBNC T | C11: PD1
A12: 106 | B12: GDRAZ N | C12: PD1
A13: 107 | B13: POUNY P | C13: PD1
A14: 108 | C14: PD1
A15: 109 | B15: FLDIN T | C15: PD1
A16: 110 | B16: KIGNY P | C16: PD1
A17: 111 | B17: HASTX D | C17: PD1
A18: 112 | B18: SVANY P | C18: PD1
A19: 113 | B19: STRCT P | C19: PD1
A20: 114 | B20: CHENY P | C20: PD1
A21: 115 | B21: BAYNJ N | C21: PD1
A22: 116 | B22: ORACT P | C22: PD1
A23: 117 | B23: EZPRA N | C23: PD1
A24: 118 | B24: EZRPA N | C24: PD1
A25: 119 | B25: ALEVA P | C25: PD1
A26: PD2
A27: 122 | B27: BETPA P | C27: PD2
A28: 123 | B28: EZRPA S | C28: PD2
A29: 124 | B29: WBAPA P | C29: PD2
A30: 125 | B30: EZRPA S | C30: PD2
A31: 126 | B31: RICVA P | C31: PD2
A32: 127 | B32: 1170 P | C32: PD2
A33: 128 | B33: SADNJ N | C33: PD2
A34: 129 | B34: CAHSC T | C34: PD2
A35: 130 | B35: CHRDE P | C35: PD2
A36: 131 | B36: OREPA P | C36: PD2
A37: 132 | B37: BLVNY P | C37: PD2
A38: 133 | B38: 1164 P | C38: PD2
... A40: 135 | B40: PARNJ P | C40: PD2
A41: 136 | C41: PD2
...

Sheet Cube Utilization Report
A1: BETPA Twilight Cube Utilization Report
A2: Weekly Report | G2: Daily Report
A4: =Pivots!A4 -> 45717 | G4: =Pivots!H4 -> 45715
A5: Sort Totals
B6: Utilization Goal | D6: 0.588 | H6: Utilization Goal | J6: 0.588
B7: Utilization Actual | D7: =GETPIVOTDATA("Sum of Total Utilization",Pivots!$A$26) -> 0.66270581 | H7: Utilization Actual | J7: =GETPIVOTDATA("Sum of Total Utilization",Pivots!$H$26) -> 0.67060432
B8: Difference | D8: =D7-D6 -> 0.074705805 | H8: Difference | J8: =J7-J6 -> 0.082604316
B10: Total Loads | D10: =GETPIVOTDATA("Sum of Total Loads",Pivots!$A$26) -> 178 | H10: Total Loads | J10: =GETPIVOTDATA("Sum of Total Loads",Pivots!$H$26) -> 27
B11: Total Cost | D11: =GETPIVOTDATA("Sum of Total Mvmt $",Pivots!$A$26) -> 156294.87 | H11: Total Cost | J11: =GETPIVOTDATA("Sum of Total Mvmt $",Pivots!$H$26) -> 23084.61
A13: Outbound Rank | G13: Outbound Rank
A14: Area | B14: Utilization | C14: To Plan | D14: Cost | E14: Loads Built | G14: Area | H14: Utilization | I14: To Plan | J14: Cost | K14: Loads Built
A15: {=Pivots!A27:A31} -> PD5 | B15: {=Pivots!B27:B31} -> 0.71329116 | C15: =B15-$D$6 -> 0.12529116 | D15: {=Pivots!C27:C31} -> 70490.02 | E15: {=Pivots!D27:D31} -> 55 | G15: {=Pivots!H27:H31} -> PD3 | H15: {=Pivots!I27:I31} -> 0.7487262 | I15: =H15-$J$6 -> 0.1607262 | J15: {=Pivots!J27:J31} -> 3745.93 | K15: {=Pivots!K27:K31} -> 4
A16: PD3 | B16: 0.68727221 | C16: =B16-$D$6 -> 0.099272206 | D16: 32751.34 | E16: 34 | G16: PD5 | H16: 0.73769151 | I16: =H16-$J$6 -> 0.14969151 | J16: 10267.14 | K16: 8
A17: PD2 | B17: 0.6640998 | C17: =B17-$D$6 -> 0.076099805 | D17: 6544.9 | E17: 27 | G17: PD1 | H17: 0.64681377 | I17: =H17-$J$6 -> 0.058813773 | J17: 3525.02 | K17: 9
A18: PD1 | B18: 0.63246422 | C18: =B18-$D$6 -> 0.044464221 | D18: 20490.19 | E18: 42 | G18: PD2 | H18: 0.58862827 | I18: =H18-$J$6 -> 0.00062826603 | J18: 687.19 | K18: 4
A19: PD4 | B19: 0.56458152 | C19: =B19-$D$6 -> -0.023418481 | D19: 26018.42 | E19: 20 | G19: PD4 | H19: 0.55421687 | I19: =H19-$J$6 -> -0.033783133 | J19: 4859.33 | K19: 2
A21: Top 5 Best Destinations | G21: Top 5 Best Destinations
A22: Destination | B22: Loaded Cube | C22: Cube Capacity | D22: Utilization | E22: Cost | G22: Destination | H22: Loaded Cube | I22: Cube Capacity | J22: Utilization | K22: Cost
A23: {=Pivots!A9:E13} -> ALLPA P | B23: 3288 | C23: 3830 | D23: 0.85848564 | E23: 26 | G23: {=Pivots!H9:L13} -> NBACA D | H23: 3264 | I23: 3818 | J23: 0.85489785 | K23: 4645.13
A24: FLDIN T | B24: 3216 | C24: 3830 | D24: 0.83968668 | E24: 1172.45 | G24: SMAGA T | H24: 3228 | I24: 3830 | J24: 0.84281984 | K24: 1501.81
A25: NBACA D | B25: 16006 | C25: 19138 | D25: 0.83634654 | E25: 21120.73 | G25: BURMD N | H25: 3129 | I25: 3818 | J25: 0.81953903 | K25: 332.94
A26: SMAGA T | B26: 17330 | C26: 21132 | D26: 0.82008329 | E26: 8017.85 | G26: NASNY P | H26: 1506 | I26: 1982 | J26: 0.75983855 | K26: 109.19
A27: EMPCA T | B27: 11974 | C27: 15284 | D27: 0.78343366 | E27: 17249.89 | G27: EMPCA T | H27: 2893 | I27: 3818 | J27: 0.75772656 | K27: 4118.14
A29: Top 5 Most to Gain Destinations | G29: Top 5 Most to Gain Destinations
A30: Destination | B30: Loaded Cube | C30: Cube Capacity | D30: Utilization | E30: Cost | G30: Destination | H30: Loaded Cube | I30: Cube Capacity | J30: Utilization | K30: Cost
A31: {=Pivots!A18:E22} -> CRBNJ N | B31: 112 | C31: 3230 | D31: 0.034674923 | E31: 221.85 | G31: {=Pivots!H18:L22} -> SADNJ N | H31: 632 | I31: 3830 | J31: 0.16501305 | K31: 212
A32: SDFAS D | B32: 578 | C32: 3964 | D32: 0.14581231 | E32: 1201.54 | G32: EZRPA N | H32: 790 | I32: 3830 | J32: 0.20626632 | K32: 182.58
A33: SADNJ N | B33: 2514 | C33: 9630 | D33: 0.26105919 | E33: 529.47 | G33: MEANJ N | H33: 968 | I33: 3818 | J33: 0.25353588 | K33: 214.2
A34: CHEMA T | B34: 1021 | C34: 3230 | D34: 0.31609907 | E34: 560.27 | G34: M43NY N | H34: 2079 | I34: 3450 | J34: 0.6026087 | K34: 184.37
A35: PHLPA P | B35: 1246 | C35: 3830 | D35: 0.32532637 | E35: 216.75 | G35: BAYNJ N | H35: 5128 | I35: 7660 | J35: 0.6694517 | K35: 408
A37: Outbounds
A38: PD1
B39: Utilization Goal | D39: 0.588 | H39: Utilization Goal | J39: 0.588
B40: Utilization Actual | D40: =_xlfn.XLOOKUP(A38,$A$14:$A$19,$B$14:$B$19) -> 0.63246422 | H40: Utilization Actual | J40: =_xlfn.XLOOKUP(A38,$G$14:$G$19,$H$14:$H$19) -> 0.64681377
B41: Difference | D41: =D40-D39 -> 0.044464221 | H41: Difference | J41: =J40-J39 -> 0.058813773
B43: Total Loads | D43: =_xlfn.XLOOKUP(A38,$A$14:$A$19,$E$14:$E$19) -> 42 | H43: Total Loads | J43: =_xlfn.XLOOKUP(A38,$G$14:$G$19,$K$14:$K$19) -> 9
B44: Total Cost | D44: =_xlfn.XLOOKUP(A38,$A$14:$A$19,$D$14:$D$19) -> 20490.19 | H44: Total Cost | J44: =_xlfn.XLOOKUP(A38,$G$14:$G$19,$J$14:$J$19) -> 3525.02
A46: Top 5 Best Destinations | G46: Top 5 Best Destinations
A47: Destination | B47: Loaded Cube | C47: Cube Capacity | D47: Utilization | E47: Cost | G47: Destination | H47: Loaded Cube | I47: Cube Capacity | J47: Utilization | K47: Cost
A48: {=Pivots!A37:E39} -> FLDIN T | B48: 3216 | C48: 3830 | D48: 0.83968668 | E48: 1172.45 | G48: =IF(Pivots!H37<>"Grand Total",Pivots!H37,"") -> MEBNC T | H48: =IF(G48<>"",Pivots!I37,"") -> 5608 | I48: =IF($G$48<>"",Pivots!J37,"") -> 7636 | J48: =IF($G$48<>"",Pivots!K37,"") -> 0.73441592 | K48: =IF($G$48<>"",Pivots!L37,"") -> 1854.44
...
